<mujoco model="pi">
  <compiler angle="radian" meshdir="../meshes/"/>

  <default>
    <joint damping="0.001" armature="0.01" frictionloss="0.1"/>
  </default>
  
  <asset>
    <mesh name="baselink_1" file="baselink_1.STL"/>
    <mesh name="l_hip_pitch_link" file="l_hip_pitch_link.STL"/>
    <mesh name="l_hip_roll_link" file="l_hip_roll_link.STL"/>
    <mesh name="l_thigh_link" file="l_thigh_link.STL"/>
    <mesh name="l_calf_link" file="l_calf_link.STL"/>
    <mesh name="l_ankle_pitch_link" file="l_ankle_pitch_link.STL"/>
    <mesh name="l_ankle_roll_link" file="l_ankle_roll_link.STL"/>
    <mesh name="foot" file="foot.STL" scale="0.001 0.001 0.001"/>
    <mesh name="r_hip_pitch_link" file="r_hip_pitch_link.STL"/>
    <mesh name="r_hip_roll_link" file="r_hip_roll_link.STL"/>
    <mesh name="r_thigh_link" file="r_thigh_link.STL"/>
    <mesh name="r_calf_link" file="r_calf_link.STL"/>
    <mesh name="r_ankle_pitch_link" file="r_ankle_pitch_link.STL"/>
    <mesh name="r_ankle_roll_link" file="r_ankle_roll_link.STL"/>
  </asset>

  <worldbody>
    <body name="base_link" pos="0.0 0.0 0.36">
      <inertial pos="0.00071885 2.781e-05 0.023702" quat="0.705115 -0.000892642 -0.000400218 0.709092" mass="1.94351" diaginertia="0.0108944 0.0104768 0.00389879"/>
      <joint name="floating_base_joint" type="free" limited="false" actuatorfrclimited="false"/>
      <geom type="mesh" contype="0" conaffinity="0" group="1" density="0" rgba="1 1 1 1" mesh="baselink_1"/>
      <geom size="0.085 0.075 0.075" pos="0 0 0.08" type="box" rgba="1 1 1 1"/>
      <site name='imu' size='0.01' pos='0.0 0 0.0'/>


      <body name="r_hip_pitch_link" pos="-5.1979e-05 -0.0233 -0.033">
        <inertial pos="0.00136979 -0.0311672 0.0002713" quat="0.443024 0.552233 -0.448007 0.545947" mass="0.398576" diaginertia="0.000125564 0.000105619 9.66873e-05"/>
        <joint name="r_hip_pitch_joint" pos="0 0 0" axis="0 1 0" range="-1.5 1.5"  damping="0.1"/>
        <geom type="mesh" contype="0" conaffinity="0" group="1" density="0" rgba="0.75294 0.75294 0.75294 1" mesh="r_hip_pitch_link"/>
        <geom size="0.025 0.025 0.025" pos="0 -0.06 0" type="box" rgba="0.75294 0.75294 0.75294 1"/>
        <body name="r_hip_roll_link" pos="0.00025 -0.0568 0">
          <inertial pos="0.00098441 -0.0339458 -0.0612495" quat="0.704737 0.027725 0.0285958 0.70835" mass="0.485718" diaginertia="0.000574153 0.000484944 0.000220223"/>
          <joint name="r_hip_roll_joint" pos="0 0 0" axis="1 0 0" range="-0.38 1.2"  damping="0.1"/>
          <geom type="mesh" contype="0" conaffinity="0" group="1" density="0" rgba="0.75294 0.75294 0.75294 1" mesh="r_hip_roll_link"/>
          <geom size="0.0005 0.0005 0.0005" type="box" rgba="0.75294 0.75294 0.75294 1"/>
          <body name="r_thigh_link" pos="-0.00025 0 -0.06925">
            <inertial pos="0 0.00116854 -0.047559" quat="0.749712 0.661764 0 0" mass="0.10938" diaginertia="0.0001194 9.02029e-05 5.69171e-05"/>
            <joint name="r_thigh_joint" pos="0 0 0" axis="0 0 1" range="-1 1"  damping="0.1"/>
            <geom type="mesh" contype="0" conaffinity="0" group="1" density="0" rgba="0.75294 0.75294 0.75294 1" mesh="r_thigh_link"/>
            <geom size="0.0005 0.0005 0.0005" type="box" rgba="0.75294 0.75294 0.75294 1"/>
            <body name="r_calf_link" pos="0 -0.0027 -0.07025">
              <inertial pos="-1.362e-05 -0.00276237 -0.0700557" quat="0.999996 0.000151905 -0.00210869 0.00182335" mass="0.80287" diaginertia="0.00372691 0.00371467 0.000183917"/>
              <joint name="r_calf_joint" pos="0 0 0" axis="0 1 0" range="0 2.2"  damping="0.1"/>
              <geom type="mesh" contype="0" conaffinity="0" group="1" density="0" rgba="0.75294 0.75294 0.75294 1" mesh="r_calf_link"/>
              <geom size="0.0005 0.0005 0.0005" type="box" rgba="0.75294 0.75294 0.75294 1"/>
              <body name="r_ankle_pitch_link" pos="0 0 -0.14">
                <inertial pos="0.00655369 0.00218609 -1.446e-05" quat="0.0129996 0.707174 -0.0129826 0.706801" mass="0.165583" diaginertia="0.00027198 0.000184707 0.000120153"/>
                <joint name="r_ankle_pitch_joint" pos="0 0 0" axis="0 1 0" range="-0.8 0.8"  damping="0.1"/>
                <geom type="mesh" contype="0" conaffinity="0" group="1" density="0" rgba="0.75294 0.75294 0.75294 1" mesh="r_ankle_pitch_link"/>
                <geom size="0.035 0.0325 0.0225" type="box" rgba="0.75294 0.75294 0.75294 1"/>
                <body name="r_ankle_roll_link" pos="0.07525 0.0027 0">
                  <inertial pos="0.00265784 0.00017568 -0.0126664" quat="0.559425 0.431421 0.433461 0.559492" mass="0.622349" diaginertia="0.00146851 0.00135082 0.000403903"/>
                  <joint name="r_ankle_roll_joint" pos="0 0 0" axis="1 0 0" range="-0.6 0.6"  damping="0.1"/>
                  <geom type="mesh" contype="0" conaffinity="0" group="1" density="0" rgba="0.75294 0.75294 0.75294 1" mesh="r_ankle_roll_link"/>
                  <geom pos="0.036 -0.036 -0.0479" quat="0.707105 0 0 0.707108" type="mesh" rgba="0.75294 0.75294 0.75294 1" group="3" mesh="foot"/>
                </body>
              </body>
            </body>
          </body>
        </body>
      </body>

      <body name="l_hip_pitch_link" pos="-5.1979e-05 0.0233 -0.033">
        <inertial pos="0.00136864 0.0306252 0.0002713" quat="0.557997 0.438077 -0.567439 0.418021" mass="0.398576" diaginertia="0.000124246 0.000104469 9.64753e-05"/>
        <joint name="l_hip_pitch_joint" pos="0 0 0" axis="0 1 0" range="-1.5 1.5"  damping="0.1"/>
        <geom type="mesh" contype="0" conaffinity="0" group="1" density="0" rgba="0.75294 0.75294 0.75294 1" mesh="l_hip_pitch_link"/>
        <geom size="0.025 0.025 0.025" pos="0 0.06 0" type="box" rgba="0.75294 0.75294 0.75294 1"/>
        <body name="l_hip_roll_link" pos="0 0.0568 0">
          <inertial pos="0.00098441 0.00013641 -0.0612495" quat="0.704579 0.0290139 0.027293 0.708507" mass="0.485718" diaginertia="0.000574155 0.000484944 0.000220212"/>
          <joint name="l_hip_roll_joint" pos="0 0 0" axis="1 0 0" range="-0.38 1.2"  damping="0.1"/>
          <geom type="mesh" contype="0" conaffinity="0" group="1" density="0" rgba="0.75294 0.75294 0.75294 1" mesh="l_hip_roll_link"/>
          <geom size="0.0005 0.0005 0.0005" type="box" rgba="0.75294 0.75294 0.75294 1"/>
          <body name="l_thigh_link" pos="0 0 -0.06925">
            <inertial pos="0 -0.00095496 -0.0236847" quat="0.660453 0.750867 0 0" mass="0.10938" diaginertia="0.00011979 9.06194e-05 5.68806e-05"/>
            <joint name="l_thigh_joint" pos="0 0 0" axis="0 0 1" range="-1 1"  damping="0.1"/>
            <geom type="mesh" contype="0" conaffinity="0" group="1" density="0" rgba="0.75294 0.75294 0.75294 1" mesh="l_thigh_link"/>
            <geom size="0.0005 0.0005 0.0005" type="box" rgba="0.75294 0.75294 0.75294 1"/>
            <body name="l_calf_link" pos="0 0 -0.07025">
              <inertial pos="-1.362e-05 0.00276237 -0.0700557" quat="0.999997 -0.000158839 0.00210677 -0.00144397" mass="0.80287" diaginertia="0.00372691 0.00371467 0.000183917"/>
              <joint name="l_calf_joint" pos="0 0 0" axis="0 1 0" range="0 2.2"  damping="0.1"/>
              <geom type="mesh" contype="0" conaffinity="0" group="1" density="0" rgba="0.75294 0.75294 0.75294 1" mesh="l_calf_link"/>
              <geom size="0.0005 0.0005 0.0005" type="box" rgba="0.75294 0.75294 0.75294 1"/>
              <body name="l_ankle_pitch_link" pos="0 0 -0.14">
                <inertial pos="0.00655369 -0.00218609 1.446e-05" quat="-0.0129826 0.706801 0.0129996 0.707174" mass="0.165583" diaginertia="0.00027198 0.000184707 0.000120153"/>
                <joint name="l_ankle_pitch_joint" pos="0 0 0" axis="0 1 0" range="-0.8 0.8"  damping="0.1"/>
                <geom type="mesh" contype="0" conaffinity="0" group="1" density="0" rgba="0.75294 0.75294 0.75294 1" mesh="l_ankle_pitch_link"/>
                <geom size="0.035 0.0325 0.0225" type="box" rgba="0.75294 0.75294 0.75294 1"/>
                <body name="l_ankle_roll_link" pos="0.07525 0 0">
                  <inertial pos="0.00265784 0.00017568 -0.0126664" quat="0.559425 0.431421 0.433461 0.559492" mass="0.622349" diaginertia="0.00146851 0.00135082 0.000403903"/>
                  <joint name="l_ankle_roll_joint" pos="0 0 0" axis="1 0 0" range="-0.6 0.6"  damping="0.1"/>
                  <geom type="mesh" contype="0" conaffinity="0" group="1" density="0" rgba="0.75294 0.75294 0.75294 1" mesh="l_ankle_roll_link"/>
                  <geom pos="0.036 -0.036 -0.0479" quat="0.707105 0 0 0.707108" type="mesh" rgba="0.75294 0.75294 0.75294 1" group="3" mesh="foot"/>
                </body>
              </body>
            </body>
          </body>
        </body>
      </body>

    </body>
  </worldbody>

  <actuator>
      <!-- 其他执行器 -->
    <motor name="r_hip_pitch_joint" joint="r_hip_pitch_joint" gear="1" ctrllimited="true" ctrlrange="-16 16" />
    <motor name="r_hip_roll_joint" joint="r_hip_roll_joint" gear="1" ctrllimited="true" ctrlrange="-16 16" />
    <motor name="r_thigh_joint" joint="r_thigh_joint" gear="1" ctrllimited="true" ctrlrange="-16 16" />
    <motor name="r_calf_joint" joint="r_calf_joint" gear="1" ctrllimited="true" ctrlrange="-16 16" />
    <motor name="r_ankle_pitch_joint" joint="r_ankle_pitch_joint" gear="1" ctrllimited="true" ctrlrange="-16 16" />
    <motor name="r_ankle_roll_joint" joint="r_ankle_roll_joint" gear="1" ctrllimited="true" ctrlrange="-16 16" />
    <motor name="l_hip_pitch_joint" joint="l_hip_pitch_joint" gear="1" ctrllimited="true" ctrlrange="-16 16" /> 
    <motor name="l_hip_roll_joint" joint="l_hip_roll_joint" gear="1" ctrllimited="true" ctrlrange="-16 16" />
    <motor name="l_thigh_joint" joint="l_thigh_joint" gear="1" ctrllimited="true" ctrlrange="-16 16" />
    <motor name="l_calf_joint" joint="l_calf_joint" gear="1" ctrllimited="true" ctrlrange="-16 16" />
    <motor name="l_ankle_pitch_joint" joint="l_ankle_pitch_joint" gear="1" ctrllimited="true" ctrlrange="-16 16" />
    <motor name="l_ankle_roll_joint" joint="l_ankle_roll_joint" gear="1" ctrllimited="true" ctrlrange="-16 16" />
  </actuator>

  <sensor>
    <!-- Position sensors -->
    <actuatorpos name="r_hip_pitch_joint_p" actuator="r_hip_pitch_joint" user="13"/>
    <actuatorpos name="r_hip_roll_joint_p" actuator="r_hip_roll_joint" user="13"/>
    <actuatorpos name="r_thigh_joint_p" actuator="r_thigh_joint" user="13"/>
    <actuatorpos name="r_calf_joint_p" actuator="r_calf_joint" user="13"/>
    <actuatorpos name="r_ankle_pitch_joint_p" actuator="r_ankle_pitch_joint" user="13"/>
    <actuatorpos name="r_ankle_roll_joint_p" actuator="r_ankle_roll_joint" user="13"/>
    <actuatorpos name="l_hip_pitch_joint_p" actuator="l_hip_pitch_joint" user="13"/>
    <actuatorpos name="l_hip_roll_joint_p" actuator="l_hip_roll_joint" user="13"/>
    <actuatorpos name="l_thigh_joint_p" actuator="l_thigh_joint" user="13"/>
    <actuatorpos name="l_calf_joint_p" actuator="l_calf_joint" user="13"/>
    <actuatorpos name="l_ankle_pitch_joint_p" actuator="l_ankle_pitch_joint" user="13"/>
    <actuatorpos name="l_ankle_roll_joint_p" actuator="l_ankle_roll_joint" user="13"/>
  
    <!-- Velocity sensors -->
    <actuatorvel name="r_hip_pitch_joint_v" actuator="r_hip_pitch_joint" user="13" noise="1e-3"/>
    <actuatorvel name="r_hip_roll_joint_v" actuator="r_hip_roll_joint" user="13" noise="1e-3"/>
    <actuatorvel name="r_thigh_joint_v" actuator="r_thigh_joint" user="13" noise="1e-3"/>
    <actuatorvel name="r_calf_joint_v" actuator="r_calf_joint" user="13" noise="1e-3"/>
    <actuatorvel name="r_ankle_pitch_joint_v" actuator="r_ankle_pitch_joint" user="13" noise="1e-3"/>
    <actuatorvel name="r_ankle_roll_joint_v" actuator="r_ankle_roll_joint" user="13" noise="1e-3"/>
    <actuatorvel name="l_hip_pitch_joint_v" actuator="l_hip_pitch_joint" user="13" noise="1e-3"/>
    <actuatorvel name="l_hip_roll_joint_v" actuator="l_hip_roll_joint" user="13" noise="1e-3"/>
    <actuatorvel name="l_thigh_joint_v" actuator="l_thigh_joint" user="13" noise="1e-3"/>
    <actuatorvel name="l_calf_joint_v" actuator="l_calf_joint" user="13" noise="1e-3"/>
    <actuatorvel name="l_ankle_pitch_joint_v" actuator="l_ankle_pitch_joint" user="13" noise="1e-3"/>
    <actuatorvel name="l_ankle_roll_joint_v" actuator="l_ankle_roll_joint" user="13" noise="1e-3"/>

    <!-- Force sensors -->
    <actuatorfrc name="r_hip_pitch_joint_f" actuator="r_hip_pitch_joint" user="13" noise="1e-3"/>
    <actuatorfrc name="r_hip_roll_joint_f" actuator="r_hip_roll_joint" user="13" noise="1e-3"/>
    <actuatorfrc name="r_thigh_joint_f" actuator="r_thigh_joint" user="13" noise="1e-3"/>
    <actuatorfrc name="r_calf_joint_f" actuator="r_calf_joint" user="13" noise="1e-3"/>
    <actuatorfrc name="r_ankle_pitch_joint_f" actuator="r_ankle_pitch_joint" user="13" noise="1e-3"/>
    <actuatorfrc name="r_ankle_roll_joint_f" actuator="r_ankle_roll_joint" user="13" noise="1e-3"/>
    <actuatorfrc name="l_hip_pitch_joint_f" actuator="l_hip_pitch_joint" user="13" noise="1e-3"/>
    <actuatorfrc name="l_hip_roll_joint_f" actuator="l_hip_roll_joint" user="13" noise="1e-3"/>
    <actuatorfrc name="l_thigh_joint_f" actuator="l_thigh_joint" user="13" noise="1e-3"/>
    <actuatorfrc name="l_calf_joint_f" actuator="l_calf_joint" user="13" noise="1e-3"/>
    <actuatorfrc name="l_ankle_pitch_joint_f" actuator="l_ankle_pitch_joint" user="13" noise="1e-3"/>
    <actuatorfrc name="l_ankle_roll_joint_f" actuator="l_ankle_roll_joint" user="13" noise="1e-3"/>

    <framequat name='orientation' objtype='site' noise='0.001' objname='imu'/>
    <framepos name='position' objtype='site' noise='0.001' objname='imu'/>
    <gyro name='angular-velocity' site='imu' noise='0.005' cutoff='34.9'/>
    <velocimeter name='linear-velocity' site='imu' noise='0.001' cutoff='30'/>
    <accelerometer name='linear-acceleration' site='imu' noise='0.005' cutoff='157'/>
    <magnetometer name='magnetometer' site='imu'/>

  </sensor>

</mujoco>
